Traceback (most recent call last):
  File "/usr/share/miniconda/envs/test/lib/python3.7/site-packages/jupyter_cache/executors/utils.py", line 64, in single_nb_execution
    **kwargs,
  File "/usr/share/miniconda/envs/test/lib/python3.7/site-packages/nbclient/client.py", line 1204, in execute
    return NotebookClient(nb=nb, resources=resources, km=km, **kwargs).execute()
  File "/usr/share/miniconda/envs/test/lib/python3.7/site-packages/nbclient/util.py", line 84, in wrapped
    return just_run(coro(*args, **kwargs))
  File "/usr/share/miniconda/envs/test/lib/python3.7/site-packages/nbclient/util.py", line 62, in just_run
    return loop.run_until_complete(coro)
  File "/usr/share/miniconda/envs/test/lib/python3.7/asyncio/base_events.py", line 587, in run_until_complete
    return future.result()
  File "/usr/share/miniconda/envs/test/lib/python3.7/site-packages/nbclient/client.py", line 664, in async_execute
    cell, index, execution_count=self.code_cells_executed + 1
  File "/usr/share/miniconda/envs/test/lib/python3.7/site-packages/nbclient/client.py", line 965, in async_execute_cell
    await self._check_raise_for_error(cell, cell_index, exec_reply)
  File "/usr/share/miniconda/envs/test/lib/python3.7/site-packages/nbclient/client.py", line 862, in _check_raise_for_error
    raise CellExecutionError.from_cell_and_msg(cell, exec_reply_content)
nbclient.exceptions.CellExecutionError: An error occurred while executing the following cell:
------------------
function = get_function('P19367')
------------------

[0;31m---------------------------------------------------------------------------[0m
[0;31mValueError[0m                                Traceback (most recent call last)
[0;32m/tmp/ipykernel_3763/3599409857.py[0m in [0;36m<module>[0;34m[0m
[0;32m----> 1[0;31m [0mfunction[0m [0;34m=[0m [0mget_function[0m[0;34m([0m[0;34m'P19367'[0m[0;34m)[0m[0;34m[0m[0;34m[0m[0m
[0m
[0;32m~/work/Sabueso/Sabueso/sabueso/protein/get_function.py[0m in [0;36mget_function[0;34m(item)[0m
[1;32m     19[0m [0;34m[0m[0m
[1;32m     20[0m [0;34m[0m[0m
[0;32m---> 21[0;31m     [0mfunction_uniprotkb_XMLDict[0m [0;34m=[0m [0mget_function_from_uniprotkb_XMLDict[0m[0;34m([0m[0mitem_uniprotkb_XMLDict[0m[0;34m)[0m[0;34m[0m[0;34m[0m[0m
[0m[1;32m     22[0m [0;34m[0m[0m
[1;32m     23[0m     [0mcard[0m[0;34m.[0m[0muniprot_function[0m [0;34m=[0m [0mfunction_uniprotkb_XMLDict[0m[0;34m[[0m[0;34m'function'[0m[0;34m][0m[0;34m[0m[0;34m[0m[0m

[0;32m~/work/Sabueso/Sabueso/sabueso/tools/sabueso_UniProtKB_XMLDict/get_function.py[0m in [0;36mget_function[0;34m(item, entity)[0m
[1;32m     21[0m [0;34m[0m[0m
[1;32m     22[0m             [0;32mif[0m [0mtype[0m[0;34m([0m[0mcomment[0m[0;34m)[0m[0;34m!=[0m[0mOrderedDict[0m[0;34m:[0m[0;34m[0m[0;34m[0m[0m
[0;32m---> 23[0;31m                 [0;32mraise[0m [0mValueError[0m[0;34m([0m[0;34m"Comment type not recognized for function"[0m[0;34m)[0m[0;34m[0m[0;34m[0m[0m
[0m[1;32m     24[0m [0;34m[0m[0m
[1;32m     25[0m             [0mcomment_text[0m [0;34m=[0m [0mcomment[0m[0;34m[[0m[0;34m'text'[0m[0;34m][0m[0;34m[0m[0;34m[0m[0m

[0;31mValueError[0m: Comment type not recognized for function
ValueError: Comment type not recognized for function

